Workbook

Sheet DATA
A1: DATA PENDIDIK DAN TENAGA KEPENDIDIKAN
A2: SMA NEGERI I BATU
A3: TAHUN 2022
A5: NO | B5: N A M A | C5: TEMPAT, TANGGAL LAHIR | D5: JENIS KEL. | G5: NIP TANPA SPASI | H5: NIP | I5: STATUS KEPEG. | J5: PANGKAT | O5: TMT CPNS/ PENGANGKA TAN I | P5: MASA KERJA | V5: JENJANG PEND. | W5: JURUSAN | X5: TAHUN LULUS | Y5: CATATAN | AA5: KELAS JABATAN / MAPEL YANG DIAMPU | AB5: NUPTK | AE5: MASA PENSIUN | AG5: No Peserta Sertifikasi Pendidik | AH5: Tanggal Sertifikasi Pendidik | AI5: NRG | AJ5: Agama | AK5: Alamat Jalan | AL5: RT | AM5: RW | AN5: Nama Dusun | AO5: Desa/Kelurahan | AP5: Kecamatan | AQ5: Kode Pos | AR5: Nomor HP | AS5: Email | AT5: NO. SK CPNS | AU5: Tanggal CPNS | AV5: TMT CPNS | AW5: SK PNS | AX5: TANGGAL PNS | AY5: TMT PNS | AZ5: Lembaga Pengangkatan | BA5: NO. SK TERAKHIR | BB5: Tanggal SK TERAKHIR | BC5: TMT SK TERAKHIR | BD5: Lembaga Pengangkatan | BE5: Golongan | BF5: No. SK Jab. Fungsional | BG5: Tgl. SK Jab. Fungsional | BH5: Nama Ibu Kandung | BI5: Status Perkawinan | BJ5: Nama Suami/Istri | BK5: NIP Suami/Istri | BL5: Pekerjaan Suami/Istri | BM5: Sudah Lisensi Kepala Sekolah | BN5: NPWP | BO5: Nomor Rekening Bank Jatim | BP5: Nomor KTP | BQ5: Nomor HP | BR5: Tanda Penghargaan Satya Lencana (terakhir)
J6: PANG/GOL | K6: GOL | L6: TMT GOL. | M6: MASA KERJA | P6: CPNS | R6: GOLONGAN | T6: SELURUHNYA | Y6: MUTASI | Z6: K E T | AD6: LAHIR | AE6: BLN | AF6: THN | BV6: TAHUN 2021/2022
E7: L | F7: P | M7: THN | N7: BLN | P7: THN | Q7: BLN | R7: THN | S7: BLN | T7: THN | U7: BLN | AC7: bln | AD7: thn | BR7: Nomor | BS7: Tanggal | BT7: Yang ke | BV7: Maker Gol | BX7: Maker Kesel | BY7: Sertifikat Pendidik
A8: 1 | B8: Edy Parlindungan.S.Pd,M.M | C8: Maga, 26 Maret 1963 | E8: 1 | G8: 19630326 1989031007 | H8: 19630326 1989031007 | I8: PNS | J8: Pembina Tingkat I | K8: IV/b | L8: 41365 | T8: 36 | U8: 8 | V8: S2 | X8: 2009 | AA8: PENDIDIKAN IPS | AB8: 4658741642200020 | AE8: 45017 | AF8: 2023 | AJ8: Islam | AK8: Jl. K.H. Wahid Hasyim | AL8: 9 | AM8: 3 | AO8: Gading | AP8: Bululawang | AQ8: 65171 | AR8: 08125212894
A9: 2 | B9: Ismi Yunaeni, S.Pd, M.Pd | C9: Jember,02-06-1961 | D9: P | F9: 1 | G9: 196106021985122002 | H9: 19610602 198512 2 002 | I9: PNS | J9: Pembina Tk. I, IV/b | K9: IV/b | L9: 01/04/2011 | O9: 01/12/1985 | P9: 3 | Q9: 0 | R9: 32 | S9: 7 | T9: 37 | U9: 7 | V9: S2 | X9: 2003 | Z9: MKG III/a - 1 thn | AA9: Biologi | AB9: 1934739655300002 | AC9: =MID(G9,5,2) -> 06 | AD9: =MID(G9,1,4) -> 1961 | AE9: 01/07/2021 | AF9: =AD9+60 -> 2021 | AG9: 08056819010176 | AH9: 09/12/2008 | AI9: 083429053009 | AJ9: Islam | AK9: Jl. Dewi Sartika III No. 40 Temas Batu | AL9: 2 | AM9: 10 | AN9: Temas | AO9: TEMAS | AP9: Kec. Batu | AQ9: 65315 | AR9: 085233466914 | AS9: ismiyunaeni61@gmail.com | AT9: 2242/104.3/c9.86/sk | AU9: 20 Februari 1986 | AV9: 01/12/1985 | AW9: 15875.118/I04/c/1987/SK | AX9: 30 Nopember 1987 | AY9: 01/12/1987 | AZ9: Pemerintah Propinsi | BA9: 823.4/493/212/2011 | BB9: 17 Februari 2011 | BC9: 01/04/2011 | BD9: Pemerintah Kota Batu | BE9: =K9 -> IV/b | BF9: 821.2/2379/204/2018 | BG9: 23 Oktober 2018 | BH9: - | BI9: Kawin | BJ9: R. Muhammad Zakaria | BK9: 195904071985031016 | BL9: PNS/TNI/Polri | BM9: Tidak | BN9: 486360837628000 | BO9: 0402142782 | BP9: 3579014206610002 | BQ9: 085233466914 | BV9: =R9+1 -> 33 | BX9: =T9+1 -> 38
A10: 3 | B10: Lilik Ismiati, M.Pd | C10: Malang, 26-07-1963 | D10: P | F10: 1 | G10: 196307261987032007 | H10: 19630726 198703 2 007 | I10: PNS | J10: Pembina Tk. I, IV/b | K10: IV/b | L10: 01/04/2014 | O10: 01/03/1987 | P10: 3 | Q10: 0 | R10: 31 | S10: 4 | T10: 36 | U10: 4 | V10: S2 | X10: 2011 | AA10: Biologi | AB10: 7058741643300043 | AC10: =MID(G10,5,2) -> 07 | AD10: =MID(G10,1,4) -> 1963 | AE10: 01/08/2023 | AF10: =AD10+60 -> 2023 | AG10: 09056819010168 | AH10: 27/07/2009 | AI10: 092538382009 | AJ10: Islam | AK10: Jl. Darsono Barat 19 Ngaglik Batu | AL10: 2 | AM10: 9 | AN10: Ngaglik | AO10: Ngaglik | AP10: Kec. Batu | AQ10: 65311 | AR10: 081931853666 | AS10: ismi_lilik@yahoo.com | AT10: 4935/I04/C/1987/SK | AU10: 21 Mei 1987 | AV10: 01/03/1987 | AW10: 24022/I04/C/88/SK | AX10: 17 Nopember 1988 | AY10: 01/12/1988 | AZ10: Pemerintah Pusat | BA10: 823.4/216/212/2014 | BB10: 12 Februari 2014 | BC10: 01/04/2014 | BD10: Pemerintah Kota Batu | BE10: =K10 -> IV/b | BF10: 821.2/2379/204/2018 | BG10: 23 Oktober 2018 | BH10: Nafiah | BI10: Kawin | BJ10: Sutrisno | BL10: PNS/TNI/Polri | BM10: Tidak | BN10: 486370042628000 | BO10: 0402115041 | BP10: 3579016607630001 | BQ10: 081335896486 | BV10: =R10+1 -> 32 | BX10: =T10+1 -> 37
A11: 4 | B11: Dra. Nurhidayati, Sh, M.Pd. | C11: Tulung Agung,18-9-1965 | D11: P | F11: 1 | G11: 196509181988032007 | H11: 19650918 198803 2 007 | I11: PNS | J11: Pembina Tk. I, IV/b | K11: IV/b | L11: 01/10/2013 | O11: 01/03/1988 | P11: 3 | Q11: 0 | R11: 30 | S11: 4 | T11: 35 | U11: 4 | V11: S2 | X11: 2018 | AA11: Sejarah | AB11: 3650743645300012 | AC11: =MID(G11,5,2) -> 09 | AD11: =MID(G11,1,4) -> 1965 | AE11: 01/10/2025 | AF11: =AD11+60 -> 2025 | AG11: 08056820410183 | AH11: 09/12/2008 | AI11: 085026067006 | AJ11: Islam | AK11: Jalan Cempaka No 35 RT. 03 / RW 05 Pesanggrahan Batu | AL11: 3 | AM11: 5 | AN11: Pesanggrahan | AO11: Pesanggrahan | AP11: Kec. Batu | AQ11: 65313 | AR11: 081131935878 | AS11: nurhidayatiedi@yahoo.com | AT11: 6842/104/c/1988/sk | AU11: 15 Juni 1988 | AV11: 01/03/1988 | AW11: 5421/I04/C/89/SK | AX11: 25 Maret 1989 | AY11: 01/04/1989 | AZ11: Pemerintah Pusat | BA11: 823.4/1905/212/2013 | BB11: 26 Agustus 2013 | BC11: 01/10/2013 | BD11: Pemerintah Kota Batu | BE11: =K11 -> IV/b | BF11: 821.2/2379/204/2018 | BG11: 23 Oktober 2018 | BH11: - | BI11: Kawin | BJ11: Dr. H. Edi Suhartono | BK11: 196110405198601100 | BL11: PNS/TNI/Polri | BM11: Tidak | BN11: 570732065628000 | BO11: 0402142669 | BP11: 3579015809650002 | BQ11: 08125992987 | BV11: =R11+1 -> 31 | BX11: =T11+1 -> 36
A12: 5 | B12: Drs. Sugiardi, M.M. | C12: Malang,24-06-1964 | D12: L | E12: 1 | G12: 196406241995121002 | H12: 19640624 199512 1 002 | I12: PNS | J12: Pembina Tk. I, IV/b | K12: IV/b | L12: 01/04/2019 | O12: 01/12/1995 | P12: 0 | Q12: 0 | R12: 25 | S12: 4 | T12: 25 | U12: 7 | V12: S2 | X12: 2007 | AA12: Fisika | AB12: 8956742644200022 | AC12: =MID(G12,5,2) -> 06 | AD12: =MID(G12,1,4) -> 1964 | AE12: 01/07/2024 | AF12: =AD12+60 -> 2024 | AG12: 09056818410191 | AH12: 27/07/2009 | AI12: 092437887007 | AJ12: Islam | AK12: Ir. Sukarno 149 Kel. Dadaprejo RT. 004 / RW. 008 Junrejo Batu | AL12: 4 | AM12: 8 | AO12: Dadap Rejo | AP12: Kec. Junrejo | AQ12: 65323 | AR12: 081333131509 | AS12: ardyerlina9@gmail.com | AT12: 79500/A2/KP/1995 | AU12: 1 Desember 1995 | AV12: 01/12/1995 | AW12: 74090/I04.3/KP/1997 | AX12: 31 Juni 1997 | AY12: 01/07/1997 | AZ12: Pemerintah Pusat | BA12: 823.4/935/204/2019 | BB12: 27 Februari 2019 | BC12: 01/04/2019 | BD12: Gubernur Jawa Timur | BE12: =K12 -> IV/b | BF12: 821.2/2380/204/2018 | BG12: 24 Oktober 2018 | BH12: Kariumi | BI12: Kawin | BJ12: Yayuk Yales Priyati | BL12: PNS/TNI/Polri | BM12: Tidak | BN12: 474677341628000 | BO12: 0402104309 | BP12: 3579032406640002 | BQ12: 081333131509 | BV12: =R12+1 -> 26 | BX12: =T12+1 -> 26
A13: 6 | B13: Sri Wati, S.Pd, M.M. | C13: Malang,19-04-1964 | D13: P | F13: 1 | G13: 196404191984122005 | H13: 19640419 198412 2 005 | I13: PNS | J13: Pembina, IV/a | K13: IV/a | L13: 01/10/2005 | O13: 01/12/1984 | P13: 3 | Q13: 0 | R13: 33 | S13: 6 | T13: 38 | U13: 7 | V13: S2 | X13: 2005 | AA13: Matematika | AB13: 3748742642300012 | AC13: =MID(G13,5,2) -> 04 | AD13: =MID(G13,1,4) -> 1964 | AE13: 01/05/2024 | AF13: =AD13+60 -> 2024 | AG13: 08056818010173 | AH13: 09/12/2008 | AI13: 084827056010 | AJ13: Islam | AK13: Jl. Imam Bonjol IV/14 RT. 01 / RW. 01 Sisir Batu | AL13: 1 | AM13: 1 | AO13: Sisir | AP13: Kec. Batu | AQ13: 65315 | AR13: 081805145245 | AS13: sriwatibatu1964@gmail.com | AT13: 2769/104.3.1/c9.85/sk | AU13: 19 Februari 1985 | AV13: 01/12/1984 | AW13: 19278/104/C/86/SK | AX13: 31 Oktober 1986 | AY13: 01/11/1986 | AZ13: Pemerintah Pusat | BA13: 823.4/1149/042/2005 | BB13: 1 September 2005 | BC13: 01/10/2005 | BD13: Pemerintah Kota Batu | BE13: =K13 -> IV/a | BF13: 821.2/2396/204/2018 | BG13: 24 Oktober 2018 | BH13: Sudarni | BI13: Kawin | BJ13: Abu Sufyan | BL13: PNS/TNI/Polri | BM13: Tidak | BN13: 570732107628000 | BO13: 0402023899 | BP13: 3579015900464000 | BQ13: 081805145245 | BV13: =R13+1 -> 34 | BX13: =T13+1 -> 39
A14: 7 | B14: Amantho, S.Pd | C14: Banyuwangi, 15-03-1962 | D14: L | E14: 1 | G14: 196203151985111002 | H14: 19620315 198511 1 002 | I14: PNS | J14: Pembina, IV/a | K14: IV/a | L14: 01/04/2005 | O14: 01/11/1985 | P14: 3 | Q14: 0 | R14: 32 | S14: 8 | T14: 37 | U14: 8 | V14: S1 | X14: 1997 | AA14: Geografi | AB14: 1835740641200003 | AC14: =MID(G14,5,2) -> 03 | AD14: =MID(G14,1,4) -> 1962 | AE14: 01/04/2022 | AF14: =AD14+60 -> 2022 | AG14: 09056820710167 | AH14: 27/07/2009 | AI14: 091986377013 | AJ14: Islam | AK14: Jl. Wurian No. 5 RT. 18 / RW. 04 Girimoyo Karangploso Malang | AL14: 18 | AM14: 4 | AN14: Ngambon | AO14: Girimoyo | AP14: Kec. Karangploso | AQ14: 65152 | AR14: 081555786633 | AS14: amantho@gmail.com | AT14: 3865/A2.IV.I/C/1986 | AU14: 11 Januari 1986 | AV14: 01/11/1985 | AW14: 2000/KEP/C-1/1988 | AX14: 31 Agustus 1988 | AY14: 01/09/1988 | AZ14: Pemerintah Pusat | BA14: 823.4/345/042/2005 | BB14: 7 Februari 2005 | BC14: 01/04/2005 | BD14: Pemerintah Kota Batu | BE14: =K14 -> IV/a | BF14: 821.2/2396/204/2018 | BG14: 24 Oktober 2018 | BH14: Tunik | BI14: Kawin | BJ14: Chusnul Cotimah | BK14: 196803111985032003 | BL14: PNS/TNI/Polri | BM14: Tidak | BN14: 570731984557000 | BO14: 0402024062 | BP14: 3507231503620002 | BQ14: 081555786633 | BV14: =R14+1 -> 33 | BX14: =T14+1 -> 38
A15: 8 | B15: Yayuk Harumiwati, S.Pd | C15: Malang,07-11-1961 | D15: P | F15: 1 | G15: 196111071985122002 | H15: 19611107 198512 2 002 | I15: PNS | J15: Pembina, IV/a | K15: IV/a | L15: 01/04/2006 | O15: 01/12/1985 | P15: 3 | Q15: 0 | R15: 32 | S15: 7 | T15: 37 | U15: 7 | V15: S1 | X15: 1997 | AA15: Sosiologi | AB15: 1439739614300003 | AC15: =MID(G15,5,2) -> 11 | AD15: =MID(G15,1,4) -> 1961 | AE15: 01/12/2021 | AF15: =AD15+60 -> 2021 | AG15: 08056821410174 | AH15: 31/12/2008 | AI15: 083934054018 | AJ15: Islam | AK15: Jl. Sumbersari 292 Malang | AL15: 9 | AM15: 1 | AN15: - | AO15: Kelurahan Sumbersari | AP15: Kec. Lowokwaru | AQ15: 65145 | AR15: 081216467799 | AS15: yayukharumiwati@yahoo.id.co | AT15: 2353/104.3/C9.86/SK | AU15: 20 Februari 1986 | AV15: 01/12/1985 | AW15: 15875.60/104/C/87/SK | AX15: 30 Nopember 1987 | AY15: 01/12/1987 | AZ15: Pemerintah Pusat | BA15: 823.4/66/042/2006 | BB15: 27 Februari 2006 | BC15: 01/04/2006 | BD15: Pemerintah Kota Batu | BE15: =K15 -> IV/a | BF15: 821.2/2380/204/2018 | BG15: 24 Oktober 2018 | BH15: - | BI15: Janda/Duda | BJ15: -- | BL15: Tidak bekerja | BM15: Tidak | BN15: 486370026628000 | BO15: 0402055219 | BP15: 3573054711610000 | BQ15: 081937944489 | BV15: =R15+1 -> 33 | BX15: =T15+1 -> 38
A16: 9 | B16: Ninil Agus Triastuti, S.Pd | C16: Malang,11-08-1963 | D16: P | F16: 1 | G16: 196308111985122002 | H16: 19630811 198512 2 002 | I16: PNS | J16: Pembina, IV/a | K16: IV/a | L16: 01/04/2006 | O16: 01/12/1985 | P16: 3 | Q16: 0 | R16: 32 | S16: 7 | T16: 37 | U16: 7 | V16: S1 | X16: 1998 | AA16: Bahasa Inggris | AB16: 0143741642300063 | AC16: =MID(G16,5,2) -> 08 | AD16: =MID(G16,1,4) -> 1963 | AE16: 01/09/2023 | AF16: =AD16+60 -> 2023 | AG16: 08056815710175 | AH16: 09/12/2008 | AI16: 084331055011 | AJ16: Islam | AK16: Jl. Seruni 14 RT. 03 / RW. 04 Mulyoagung Dau Malang | AL16: 3 | AM16: 4 | AN16: Mulyoagung | AO16: Mulyoagung | AP16: Kec. Dau | AQ16: 65151 | AR16: 081330007282 | AS16: ninil.trias@gmail.com | AT16: 2346/104.3/0986/sk | AU16: 20 Februari 1986 | AV16: 01/12/1985 | AW16: 14805/I04/C/87/SK | AX16: 25 Nopember 1987 | AY16: 01/12/1986 | AZ16: Pemerintah Pusat | BA16: 823.4/66/042/2006 | BB16: 27 Februari 2006 | BC16: 01/04/2006 | BD16: Pemerintah Kota Batu | BE16: =K16 -> IV/a | BF16: 821.2/2396/204/2018 | BG16: 24 Oktober 2018 | BH16: - | BI16: Kawin | BJ16: Agus Sutrisno | BL16: Wiraswasta | BM16: Tidak | BN16: 486370034657000 | BO16: 0402115009 | BP16: 3507225108630004 | BQ16: 081330007282 | BV16: =R16+1 -> 33 | BX16: =T16+1 -> 38
A17: 10 | B17: Dra. Amalia Ujinastiti | C17: Yogyakarta, 29-5-1962 | D17: P | F17: 1 | G17: 196205291989032004 | H17: 19620529 198903 2 004 | I17: PNS | J17: Pembina, IV/a | K17: IV/a | L17: 01/04/2002 | O17: 01/03/1989 | P17: 0 | Q17: 0 | R17: 31 | S17: 4 | T17: 31 | U17: 4 | V17: S1 | X17: 1987 | AA17: Kimia | AB17: 1861740641300032 | AC17: =MID(G17,5,2) -> 05 | AD17: =MID(G17,1,4) -> 1962 | AE17: 01/06/2022 | AF17: =AD17+60 -> 2022 | AG17: 08056818710190 | AH17: 09/12/2008 | AI17: 086128054003 | AJ17: Islam | AK17: Villa Sengkaling , Jl. Taman Sengkaling XII / N - 78 | AL17: 3 | AM17: 3 | AN17: Mulyoagung | AO17: Mulyoagung | AP17: Kec. Dau | AQ17: 65151 | AR17: 08123322814 | AS17: ajinastiti@gmail.com | AT17: 11205/I04/c/89/sk | AU17: 16 Juni 1989 | AV17: 01/03/1989 | AW17: 3144/I04/C/90/SK | AX17: 30 Maret 1990 | AY17: 01/04/1990 | AZ17: Pemerintah Pusat | BA17: 823.4/352/422.015/2002 | BB17: 30 Juli 2002 | BC17: 01/04/2002 | BD17: Pemerintah Kota Batu | BE17: =K17 -> IV/a | BF17: 821.2/2380/204/2018 | BG17: 24 Oktober 2018 | BH17: - | BI17: Kawin | BJ17: Iman Kuswahyono | BK17: 195710211986011002 | BL17: PNS/TNI/Polri | BM17: Tidak | BN17: 486370000657000 | BO17: 0402126710 | BP17: 3507226905620003 | BQ17: 08123322814 | BV17: =R17+1 -> 32 | BX17: =T17+1 -> 32
A18: 11 | B18: Dra. Shofiyatuz Zahra | C18: Nganjuk,12-12-1961 | D18: P | F18: 1 | G18: 196112121989022003 | H18: 19611212 198902 2 003 | I18: PNS | J18: Pembina, IV/a | K18: IV/a | L18: 01/04/2005 | O18: 01/02/1989 | P18: 0 | Q18: 0 | R18: 31 | S18: 5 | T18: 31 | U18: 5 | V18: S1 | X18: 1982 | AA18: Bahasa Indonesia | AB18: 9544739640300073 | AC18: =MID(G18,5,2) -> 12 | AD18: =MID(G18,1,4) -> 1961 | AE18: 01/01/2022 | AF18: =AD18+60+1 -> 2022 | AG18: 08056815610188 | AH18: 31/12/2008 | AI18: 084435053060 | AJ18: Islam | AK18: Jl. Imam bonjol V no 20 RT. 01 / RW. 01 Sisir Batu | AL18: 1 | AM18: 1 | AN18: Sisir | AO18: Sisir | AP18: Kec. Batu | AQ18: 65314 | AR18: 08123300782 | AS18: shofizahra@hotmail.com | AT18: 5606/104/c/89/sk | AU18: 27 Maret 1989 | AV18: 01/02/1989 | AW18: 4504/104/C/90/Sk | AX18: 30 April 1990 | AY18: 01/05/1990 | AZ18: Pemerintah Pusat | BA18: 823.4/345/042/2005, | BB18: 823.4/345/042/2005, | BC18: 01/04/2005 | BD18: Pemerintah Kota Batu | BE18: =K18 -> IV/a | BF18: 821.2/2381/204/2018 | BG18: 24 Oktober 2018 | BH18: - | BI18: Kawin | BJ18: Didik Supriadi | BK18: 196410131990101001 | BL18: PNS/TNI/Polri | BM18: Tidak | BN18: 570732073628000 | BO18: 0402040777 | BP18: 3579015212610001 | BQ18: 081334336333 | BV18: =R18+1 -> 32 | BX18: =T18+1 -> 32
A19: 12 | B19: Mudrikah Hayati, S.Pd | C19: Blitar,22-06-1963 | D19: P | F19: 1 | G19: 196306221987032006 | H19: 19630622 198703 2 006 | I19: PNS | J19: Pembina, IV/a | K19: IV/a | L19: 01/04/2006 | O19: 01/03/1987 | P19: 3 | Q19: 0 | R19: 31 | S19: 4 | T19: 36 | U19: 4 | V19: S1 | X19: 1998 | AA19: Bahasa Indonesia | AB19: 2954741642300042 | AC19: =MID(G19,5,2) -> 06 | AD19: =MID(G19,1,4) -> 1963 | AE19: 01/07/2023 | AF19: =AD19+60 -> 2023 | AG19: 08056815610179 | AH19: 31/12/2008 | AI19: 085429055019 | AJ19: Islam | AK19: Perumahan Griya Sampurna Sejahtera A2/04 Ampeldento Malang | AL19: 33 | AM19: 11 | AN19: Ampeldento | AO19: Ampeldento | AP19: Kec. Karangploso | AQ19: 65152 | AR19: 08123398624 | AS19: you_mud@yahoo.com | AT19: 3470/104/c/87/sk | AU19: 1 Mei 1987 | AV19: 01/03/1987 | AW19: 25980/I04/C/88/Sk | AX19: 15 Desember 1988 | AY19: 01/01/1989 | AZ19: Pemerintah Pusat | BA19: 823.4/66/042/2006 | BB19: 27 Februari 2006 | BC19: 01/04/2006 | BD19: Pemerintah Kota Batu | BE19: =K19 -> IV/a | BF19: 821.2/2396/204/2018 | BG19: 24 Oktober 2018 | BH19: - | BI19: Janda/Duda | BJ19: -- | BL19: Tidak bekerja | BM19: Tidak | BN19: 486360886657000 | BO19: 0402066466 | BP19: 3507236206630001 | BQ19: 08123398624 | BV19: =R19+1 -> 32 | BX19: =T19+1 -> 37
A20: 13 | B20: Tri Sakti Andayani. M.Pd | C20: Trenggalek,26-8-1965 | D20: P | F20: 1 | G20: 196508261988032015 | H20: 19650826 198803 2 015 | I20: PNS | J20: Pembina, IV/a | K20: IV/a | L20: 01/04/2005 | O20: 01/03/1988 | P20: 3 | Q20: 0 | R20: 30 | S20: 4 | T20: 35 | U20: 4 | V20: S2 | X20: 2012 | AA20: Biologi | AB20: 6158743644300023 | AC20: =MID(G20,5,2) -> 08 | AD20: =MID(G20,1,4) -> 1965 | AE20: 01/09/2025 | AF20: =AD20+60 -> 2025 | AG20: 08056819010184 | AH20: 09/12/2008 | AI20: 085831057006 | AJ20: Islam | AK20: Jl. Ir. Soekarno NO. 127 Beji Junrejo Batu | AL20: 4 | AM20: 5 | AN20: Beji | AO20: Beji | AP20: Kec. Junrejo | AQ20: 66326 | AR20: 0818387274 | AS20: trisaktiandayani@yahoo.com | AT20: 7068/104/c/1988/sk | AU20: 15 Juni 1988 | AV20: 01/03/1988 | AW20: 6849/I04/C/1989/SK | AX20: 12 April 1989 | AY20: 01/05/1989 | AZ20: Pemerintah Pusat | BA20: 823.4/345/042/2005 | BB20: 7 Februari 2005 | BC20: 01/04/2005 | BD20: Pemerintah Kota Batu | BE20: =K20 -> IV/a | BF20: 821.2/2380/204/2018 | BG20: 24 Oktober 2018 | BH20: - | BI20: Belum Kawin | BJ20: -- | BL20: Tidak bekerja | BM20: Tidak | BN20: 474677275628000 | BO20: 0402115025 | BP20: 3579036608650001 | BQ20: 085101777511 | BV20: =R20+1 -> 31 | BX20: =T20+1 -> 36
A21: 14 | B21: Drs. Sugeng Harianto | C21: Malang, 31-7-1962 | D21: L | E21: 1 | G21: 196207311990031003 | H21: 19620731 199003 1 003 | I21: PNS | J21: Pembina, IV/a | K21: IV/a | L21: 01/04/2007 | O21: 01/03/1990 | P21: 0 | Q21: 0 | R21: 30 | S21: 4 | T21: 30 | U21: 4 | V21: S1 | X21: 1989 | AA21: Pend. Agama Islam | AB21: 1063740646200003 | AC21: =MID(G21,5,2) -> 07 | AD21: =MID(G21,1,4) -> 1962 | AE21: 01/08/2022 | AF21: =AD21+60 -> 2022 | AG21: 09056812720024 | AH21: 15/12/2009 | AI21: 091588387022 | AJ21: Islam | AK21: Pinang Sepuluh N0 6 RT. 01 / RW. 08 Sidomulyo Batu | AL21: 1 | AM21: 8 | AO21: Sidomulyo | AP21: Kec. Batu | AQ21: 65317 | AR21: 082234989527 | AS21: sugengtaman06@gmail.com | AT21: 8511/I04/C/90/SK | AU21: 30 Juni 1990 | AV21: 01/03/1990 | AW21: 13008/I04/C/1991/SK | AX21: 30 Oktober 1991 | AY21: 01/11/1991 | AZ21: Pemerintah Pusat | BA21: 823.4/555/042/2007 | BB21: 39199 | BC21: 01/04/2007 | BD21: Pemerintah Kota Batu | BE21: =K21 -> IV/a | BF21: 821.2/2396/204/2018 | BG21: 24 Oktober 2018 | BH21: - | BI21: Kawin | BJ21: Kurrota Akyun | BL21: Tidak bekerja | BM21: Tidak | BN21: 474677309628000 | BO21: 0402014831 | BP21: 3579013107620001 | BQ21: 082234989527 | BV21: =R21+1 -> 31 | BX21: =T21+1 -> 31
A22: 15 | B22: Yudiono, S.Pd | C22: Malang,12-09-1965 | D22: L | E22: 1 | G22: 196509121989031017 | H22: 19650912 198903 1 017 | I22: PNS | J22: Pembina, IV/a | K22: IV/a | L22: 01/04/2008 | O22: 01/03/1989 | P22: 3 | Q22: 0 | R22: 29 | S22: 4 | T22: 34 | U22: 4 | V22: S1 | X22: 1997 | AA22: Matematika | AB22: 5244743646200073 | AC22: =MID(G22,5,2) -> 09 | AD22: =MID(G22,1,4) -> 1965 | AE22: 01/10/2025 | AF22: =AD22+60 -> 2025 | AG22: 09056818010170 | AH22: 23/10/2009 | AI22: 091839392006 | AJ22: Islam | AK22: Jl. Durian 1 RT. 01 / RW. 04 Mulyoagung Dau Malang | AL22: 4 | AM22: 1 | AN22: Dermo | AO22: Mulyoagung | AP22: Kec. Dau | AQ22: 65151 | AR22: 085649508609 | AS22: yudiono1965@yahoo.co.id | AT22: 11438/104c/89/sk | AU22: 19 Juni 1989 | AV22: 01/03/1989 | AW22: 13876/I04/C/90/SK | AX22: 31 Agustus 1990 | AY22: 01/09/1990 | AZ22: Pemerintah Pusat | BA22: 823.4/224/042/2008 | BB22: 22 Februari 2008 | BC22: 01/04/2008 | BD22: Pemerintah Kota Batu | BE22: =K22 -> IV/a | BF22: 821.2/2381/204/2018 | BG22: 24 Oktober 2018 | BH22: Tuni | BI22: Kawin | BJ22: Eni Astutik | BL22: Tidak bekerja | BM22: Tidak | BN22: 474677291657000 | BO22: 0402115114 | BP22: 3507221209650001 | BQ22: 085649508609 | BV22: =R22+1 -> 30 | BX22: =T22+1 -> 35
A23: 16 | B23: Awaludin, M.Pd | C23: Ujung Pandang,15-07-1965 | D23: L | E23: 1 | G23: 196507151993031008 | H23: 19650715 199303 1 008 | I23: PNS | J23: Pembina, IV/a | K23: IV/a | L23: 01/10/2006 | O23: 01/03/1993 | P23: 0 | Q23: 0 | R23: 27 | S23: 4 | T23: 27 | U23: 4 | V23: S2 | X23: 2012 | AA23: Matematika | AB23: 5047743644200043 | AC23: =MID(G23,5,2) -> 07 | AD23: =MID(G23,1,4) -> 1965 | AE23: 01/08/2025 | AF23: =AD23+60 -> 2025 | AG23: 09056818010177 | AH23: 27/07/2009 | AI23: 091988392005 | AJ23: Islam | AK23: Jl. Dewi Sartika III B No. 15 RT. 07 / RW. 09 Temas Batu | AL23: 7 | AM23: 9 | AN23: Temas | AO23: Temas | AP23: Kec. Batu | AQ23: 65315 | AR23: 081331264099 | AS23: awaluddin418@gmail.com | AT23: 594/118.c.1/c3/1993 | AU23: 23 Juni 1993 | AV23: 01/03/1993 | AW23: 5445a/I18.c.1/C3/1994 | AX23: 30 Nopember 1994 | AY23: 01/12/1994 | AZ23: Pemerintah Pusat | BA23: 823/1315/042/2006 | BB23: 27 Desember 2006 | BC23: 01/10/2006 | BD23: Pemerintah Kota Batu | BE23: =K23 -> IV/a | BF23: 821.2/2381/204/2018 | BG23: 24 Oktober 2018 | BH23: - | BI23: Kawin | BJ23: Endang Srigati | BL23: Wiraswasta | BM23: Tidak | BN23: 570732057628000 | BO23: 0402115122 | BP23: 3579011507650001 | BQ23: 081331264099 | BV23: =R23+1 -> 28 | BX23: =T23+1 -> 28
A24: 17 | B24: Abdul Khamid, S.Pd | C24: Malang, 21-08-1969 | D24: L | E24: 1 | G24: 196908211994031005 | H24: 19690821 199403 1 005 | I24: PNS | J24: Pembina, IV/a | K24: IV/a | L24: 01/04/2011 | O24: 01/03/1994 | P24: 0 | Q24: 0 | R24: 26 | S24: 4 | T24: 26 | U24: 4 | V24: S1 | X24: 1993 | Y24: SMAN 1 NGANTANG | AA24: PKn | AB24: 9153747649200023 | AC24: =MID(G24,5,2) -> 08 | AD24: =MID(G24,1,4) -> 1969 | AE24: 01/09/2029 | AF24: =AD24+60 -> 2029 | AG24: 08051815411520 | AH24: 31/12/2008 | AI24: 085331061011 | AK24: Jl. Salak No.12 RT 02 RW 09 Binangun Bumiaji Kec.Bumiaji BatuHidayatin | AL24: 2 | AM24: 9 | AN24: Binangun | AO24: Binangun | AP24: Bumiaji | AQ24: 65331 | AR24: 085100379225 | AS24: afabdillah@gmail.com | AT24: 53588/A2.IV.1/C/1994 | AU24: 12 September 1994 | AV24: 01/03/1994 | AW24: 50330/I04.3/KP/1996 | AX24: 29 Nopember 1996 | AY24: 01/12/1996 | AZ24: Dep. P dan K Prop. Jatim | BA24: 824.3/3676.1/101.1/2017 | BB24: 824.3/3676.1/101.1/2017 | BC24: 01/04/2011 | BD24: Pemerintah Kota Batu | BE24: =K24 -> IV/a | BF24: 821.2/2381/204/2018 | BG24: 24 Oktober 2018 | BN24: 587891094628000 | BO24: 0047183511 | BP24: 3579022108690001 | BQ24: 085100379225 | BV24: =R24+1 -> 27 | BX24: =T24+1 -> 27
A25: 18 | B25: Shinta Amalia, M.Pd | C25: Bandung,20-12-1968 | D25: P | F25: 1 | G25: 196812201994122002 | H25: 19681220 199412 2 002 | I25: PNS | J25: Pembina, IV/a | K25: IV/a | L25: 01/04/2008 | O25: 01/12/1994 | P25: 0 | Q25: 0 | R25: 25 | S25: 7 | T25: 25 | U25: 7 | V25: S2 | X25: 2011 | AA25: Kimia | AB25: 6552746648300063 | AC25: =MID(G25,5,2) -> 12 | AD25: =MID(G25,1,4) -> 1968 | AE25: 01/01/2029 | AF25: =AD25+60+1 -> 2029 | AG25: 09056818710186 | AH25: 23/10/2009 | AI25: 092240907003 | AJ25: Islam | AK25: Perum Puncak Permata Sengkaling A1 Mulyoagung Dau Malang | AL25: 1 | AM25: 6 | AO25: Sumber Sekar | AP25: Kec. Batu | AQ25: 65151 | AR25: 081252186117 | AS25: shintaamalia1968@gmail.com | AT25: 81943/A2/c/1994 | AU25: 11 November 1994 | AV25: 01/12/1994 | AW25: 2084/1/102.Kep/KP.1b.1996 | AX25: 30 Nopember 1996 | AY25: 01/12/1996 | AZ25: Pemerintah Pusat | BA25: 823.4/224/042/2008 | BB25: 22 Februari 2008 | BC25: 01/04/2008 | BD25: Pemerintah Kota Batu | BE25: =K25 -> IV/a | BF25: 821.2/2380/204/2018 | BG25: 24 Oktober 2018 | BH25: - | BI25: Kawin | BJ25: Toto Nusantara | BL25: PNS/TNI/Polri | BM25: Tidak | BN25: 474677325657000 | BO25: 0402143487 | BP25: 3507226012680001 | BQ25: 081252186117 | BV25: =R25+1 -> 26 | BX25: =T25+1 -> 26
A26: 19 | B26: Drs. Mohammad Qodri | C26: Malang,10-08-1962 | D26: L | E26: 1 | G26: 196208101995121002 | H26: 19620810 199512 1 002 | I26: PNS | J26: Pembina, IV/a | K26: IV/a | L26: 01/10/2008 | O26: 01/12/1995 | P26: 0 | Q26: 0 | R26: 24 | S26: 7 | T26: 24 | U26: 7 | V26: S1 | X26: 1986 | AA26: Biologi | AB26: 5142740641200043 | AC26: =MID(G26,5,2) -> 08 | AD26: =MID(G26,1,4) -> 1962 | AE26: 01/09/2022 | AF26: =AD26+60 -> 2022 | AG26: 09056819010190 | AH26: 27/07/2009 | AI26: 091738877005 | AJ26: Islam | AK26: Jl. Mangga 1b Ds. Klampok Singosari Malang | AL26: 2 | AM26: 2 | AN26: Krajan | AO26: Klampok | AP26: Kec. Singosari | AQ26: 65153 | AR26: 0813337498070 | AS26: mqodri62@g.mail.com | AT26: 80199/A2/KP/1995 | AU26: 23 Destember 1995 | AV26: 01/12/1995 | AW26: 81138/104.3/KP/1997 | AX26: 23 September1997 | AY26: 01/10/1997 | AZ26: Pemerintah Pusat | BA26: 823.4/1132/042/2008 | BB26: 5 Agustus 2008 | BC26: 01/10/2008 | BD26: Pemerintah Kota Batu | BE26: =K26 -> IV/a | BF26: 821.2/2380/204/2018 | BG26: 24 Oktober 2018 | BH26: Kanikyah | BI26: Kawin | BJ26: Eni Sulistiowati | BL26: Wiraswasta | BM26: Tidak | BN26: 486370075657000 | BO26: 0402016094 | BP26: 3507241008620004 | BQ26: 081333749876 | BV26: =R26+1 -> 25 | BX26: =T26+1 -> 25
A27: 20 | B27: Dra. Mustaghfiroh | C27: Malang,10-08-1966 | D27: P | F27: 1 | G27: 196601201995122002 | H27: 19660120 199512 2 002 | I27: PNS | J27: Pembina, IV/a | K27: IV/a | L27: 01/10/2008 | O27: 01/12/1995 | P27: 0 | Q27: 0 | R27: 25 | S27: 7 | T27: 25 | U27: 7 | V27: S1 | X27: 1990 | AA27: Pend. Agama Islam | AB27: 4452744646300042 | AC27: =MID(G27,5,2) -> 01 | AD27: =MID(G27,1,4) -> 1966 | AE27: 01/02/2026 | AF27: =AD27+60 -> 2026 | AG27: 09056812720044 | AH27: 15/10/2009 | AI27: 091288902013 | AJ27: Islam | AK27: Jl. Dorowati IV/13 Kel. Sisir Batu | AL27: 2 | AM27: 5 | AN27: Sisir | AO27: Sisir | AP27: Kec. Batu | AQ27: 65314 | AR27: 082229205758 | AS27: taghfirohmus@yahoo.co.id | AT27: 79074/A2/KP/1995 | AU27: 30 November 1995 | AV27: 01/12/1995 | AW27: 74093/I04.3/KP/1997 | AX27: 30 Juni 1997 | AY27: 01/07/1997 | AZ27: Pemerintah Pusat | BA27: 823.4/1132/042/2008 | BB27: 5 Agustus 2008 | BC27: 01/10/2008 | BD27: Pemerintah Kota Batu | BE27: =K27 -> IV/a | BF27: 821.2/2380/204/2018 | BG27: 24 Oktober 2018 | BH27: - | BI27: Kawin | BJ27: Alichwan Nurwiyono | BL27: Lainnya | BM27: Tidak | BN27: 486360894628000 | BO27: 0402133228 | BP27: 3579016001660002 | BQ27: 082229205758 | BV27: =R27+1 -> 26 | BX27: =T27+1 -> 26
A28: 21 | B28: Tatang Yuli Ahmadi, M.Pd | C28: Malang, 03-07-1968 | D28: L | E28: 1 | G28: 196807031993021001 | H28: 19680703 199302 1 001 | I28: PNS | J28: Pembina, IV/a | K28: IV/a | L28: 01/04/2011 | O28: 01/2/1993 | P28: 3 | Q28: 0 | R28: 24 | S28: 5 | T28: 30 | U28: 5 | V28: S2 | X28: 2012 | AA28: Bahasa Inggris | AB28: 6035746649200053 | AC28: =MID(G28,5,2) -> 07 | AD28: =MID(G28,1,4) -> 1968 | AE28: 01/08/2028 | AF28: =AD28+60 -> 2028 | AG28: 09056815710178 | AH28: 23/10/2009 | AI28: 091586407005 | AJ28: Islam | AK28: Jl. Bandulan VI No. 820 RT. 03. / RW. 03 Sukun Malang | AL28: 3 | AM28: 3 | AO28: Bandulan | AP28: Kec. Batu | AQ28: 65146 | AR28: 082132195733 | AS28: tatangyuliahmadi@gmail.com | AT28: 2062/104/C/1993/SK | AU28: 31 Maret 1993 | AV28: 01/2/1993 | AW28: 4329/I04/C/1994/SK | AX28: 3 Juni 1994 | AY28: 01/07/1994 | AZ28: Pemerintah Pusat | BA28: 823.4/493/212/2011 | BB28: 17 Februari 2011 | BC28: 01/04/2011 | BD28: Pemerintah Kota Batu | BE28: =K28 -> IV/a | BF28: 821.2/2396/204/2018 | BG28: 24 Oktober 2018 | BH28: Sunarti | BI28: Kawin | BJ28: Jhohanani | BL28: Wiraswasta | BM28: Tidak | BN28: 486370067623000 | BO28: 0402143444 | BP28: 3573040307680005 | BQ28: 082132195733 | BV28: =R28+1 -> 25 | BX28: =T28+1 -> 31
A29: 22 | B29: Ririn Andriana, M.Pd. | C29: Probolinggo,04-10-1965 | D29: P | F29: 1 | G29: 196510041996022001 | H29: 19651004 199602 2 001 | I29: PNS | J29: Pembina, IV/a | K29: IV/a | L29: 01/10/2008 | O29: 01/2/1996 | P29: 0 | Q29: 0 | R29: 24 | S29: 5 | T29: 24 | U29: 5 | V29: S2 | X29: 2012 | AA29: Bimbingan Konseling | AB29: 533674364300003 | AC29: =MID(G29,5,2) -> 10 | AD29: =MID(G29,1,4) -> 1965 | AE29: 01/11/2025 | AF29: =AD29+60 -> 2025 | AG29: 09056881010192 | AH29: 23/07/2009 | AI29: 091736892005 | AJ29: Islam | AK29: Jl. Seruni 19 RT. 03 /RW. 04 Dau Malang | AL29: 3 | AM29: 4 | AN29: Mulyoagung | AO29: Mulyoagung | AP29: Kec. Dau | AQ29: 65151 | AR29: 081334833432 | AS29: ririnandrianabintang@gmail.com | AT29: 4821/A2/KP/1996 | AU29: 29 Januari 1996 | AV29: 01/2/1996 | AW29: 81135/I04.3/KP/1997 | AX29: 23 September 1997 | AY29: 01/10/1997 | AZ29: Pemerintah Pusat | BA29: 823.4/1132/042/2008 | BB29: 5 Agustus 2008 | BC29: 01/10/2008 | BD29: Pemerintah Kota Batu | BE29: =K29 -> IV/a | BF29: 821.2/2380/204/2018 | BG29: 24 Oktober 2018 | BH29: Murtani | BI29: Kawin | BJ29: Antonius Mulyono | BK29: 196105241988031004 | BL29: PNS/TNI/Polri | BM29: Tidak | BN29: 486360902657000 | BO29: 0402022558 | BP29: 3507224410650001 | BQ29: 081334833432 | BV29: =R29+1 -> 25 | BX29: =T29+1 -> 25
A30: 23 | B30: Dra. Winda Khusmiati | C30: Malang, 01-05-1963 | D30: P | F30: 1 | G30: 196305011997032002 | H30: 19630501 199703 2 002 | I30: PNS | J30: Pembina, IV/a | K30: IV/a | L30: 01/04/2013 | O30: 01/03/1997 | P30: 0 | Q30: 0 | R30: 23 | S30: 4 | T30: 23 | U30: 4 | V30: S1 | X30: 1982 | AA30: Ekonomi | AB30: 6833741642300072 | AC30: =MID(G30,5,2) -> 05 | AD30: =MID(G30,1,4) -> 1963 | AE30: 01/06/2023 | AF30: =AD30+60 -> 2023 | AG30: 09056821010194 | AH30: 23/10/2009 | AI30: 091485382013 | AJ30: Islam | AK30: Perum Puri Indah B2 No 11 Beji Junrejo Batu | AL30: 4 | AM30: 2 | AN30: Beji | AO30: Beji | AP30: Kec. Junrejo | AQ30: 65326 | AR30: 087759629101 | AS30: indrakhusmiati@gmail.com | AT30: 19952/A2/KP/1997 | AU30: 5 Fembruari 1997 | AV30: 01/03/1997 | AW30: 83914/I04.3/KP/1998 | AX30: 31 Juli 1998 | AY30: 01/08/1998 | AZ30: Pemerintah Pusat | BA30: 823.4/452/212/2013 | BB30: 25 Februari 2013 | BC30: 01/04/2013 | BD30: Pemerintah Kota Batu | BE30: =K30 -> IV/a | BF30: 821.2/2381/204/2018 | BG30: 24 Oktober 2018 | BH30: Siti Halimah | BI30: Kawin | BJ30: Pamor Patriawan | BK30: 196110091988031006 | BL30: Tidak bekerja | BM30: Tidak | BN30: 486370125628000 | BO30: 0402142821 | BP30: 3579034105630002 | BQ30: 087759629101 | BV30: =R30+1 -> 24 | BX30: =T30+1 -> 24
A31: 24 | B31: Drs. Hari Prasetyo | C31: Ponorogo, 23-05-1967 | D31: L | E31: 1 | G31: 196705231999031003 | H31: 19670523 199903 1 003 | I31: PNS | J31: Pembina, IV/a | K31: IV/a | L31: 01/04/2013 | O31: 01/03/1999 | P31: 0 | Q31: 0 | R31: 21 | S31: 4 | T31: 21 | U31: 4 | V31: S1 | X31: 1992 | AA31: PENJASKES | AB31: 5855745647200022 | AC31: =MID(G31,5,2) -> 05 | AD31: =MID(G31,1,4) -> 1967 | AE31: 01/06/2027 | AF31: =AD31+60 -> 2027 | AG31: 09056822010196 | AH31: 23/10/2009 | AI31: 092387402002 | AJ31: Islam | AK31: Jl. Hasanuddin VI/84 RT. 04 / RW. 09 Pesanggrahan Batu | AL31: 4 | AM31: 9 | AN31: Pesanggrahan | AO31: Pesanggrahan | AP31: Kec. Batu | AQ31: 65313 | AR31: 081803878203 | AS31: harihawug@gmail.com | AT31: 35961/104/KP/1999 | AU31: 19 April 1999 | AV31: 01/03/1999 | AW31: 117680/I04.3/KP/2000 | AX31: 29 Nopember 2000 | AY31: 01/12/2000 | AZ31: Dep. P dan K Prop. Jatim | BA31: 823.4/452/212/2013 | BB31: 25 Februari 2013 | BC31: 01/04/2013 | BD31: Pemerintah Kota Batu | BE31: =K31 -> IV/a | BF31: 821.2/2381/204/2018 | BG31: 24 Oktober 2018 | BH31: Marijatun | BI31: Kawin | BJ31: Tri Retno Wulandari | BL31: Tidak bekerja | BM31: Tidak | BN31: 342412616628000 | BO31: 0402013478 | BP31: 3573012305670003 | BQ31: 081803878203 | BV31: =R31+1 -> 22 | BX31: =T31+1 -> 22
A32: 25 | B32: Drs. Puji | C32: Malang,16-02-1961 | D32: L | E32: 1 | G32: 196102161988031006 | H32: 19610216 198803 1 006 | I32: PNS | J32: Penata Tk. I, III/d | K32: III/d | L32: 01/04/2011 | O32: 01/03/1988 | P32: 0 | Q32: 0 | R32: 27 | S32: 4 | T32: 32 | U32: 4 | V32: S1 | X32: 1991 | AA32: Bimbingan Konseling | AB32: 1548739661200002 | AC32: =MID(G32,5,2) -> 02 | AD32: =MID(G32,1,4) -> 1961 | AE32: 01/03/2021 | AF32: =AD32+60 -> 2021 | AG32: 10056881010114 | AH32: 30/08/2010 | AI32: 102035872011 | AJ32: Islam | AK32: Jl. Lilin Mas No. 1 RT. 04 / RW. 02 Dadaprejo Junrejo Batu | AL32: 4 | AM32: 2 | AN32: Areng-Areng | AO32: Dadaprejo | AP32: Kec. Manekar | AQ32: 65323 | AR32: 082142924791 | AS32: drspuji@yahooco.id | AT32: 7662/104/C/88/SK | AU32: 20 Juni 1988 | AV32: 01/03/1988 | AW32: 7691/I04/C/89/Sk | AX32: 19 April 1989 | AY32: 01/05/1989 | AZ32: Pemerintah Kab/Kota | BA32: 823.3/27/SK/422.203/2011 | BB32: 5 Mei 2011 | BC32: 01/04/2011 | BD32: Pemerintah Kota Batu | BE32: =K32 -> III/d | BF32: 821.2/011/422.024/2004 | BG32: 4 Mei 2004 | BH32: Poniti | BI32: Kawin | BJ32: Endang A | BK32: 196208271984122005 | BL32: PNS/TNI/Polri | BM32: Tidak | BN32: 486370109628000 | BO32: 0402144700 | BP32: 35790031602610002 | BQ32: 082142924791 | BV32: =R32+1 -> 28 | BX32: =T32+1 -> 33
A33: 26 | B33: Rina Yuliawati, S.Pd, M.Ed | C33: Malang, 08-07-1967 | D33: P | F33: 1 | G33: 196707081989012003 | H33: 19670708 198901 2 003 | I33: PNS | J33: Penata Tk. I, III/d | K33: III/d | L33: 01/10/2011 | O33: 01/01/1989 | P33: 3 | Q33: 0 | R33: 26 | S33: 6 | T33: 34 | U33: 6 | V33: S2 | X33: 2005 | Z33: MKG II/d- 1 tahun | AA33: Bahasa Inggris | AB33: 7040745646300013 | AC33: =MID(G33,5,2) -> 07 | AD33: =MID(G33,1,4) -> 1967 | AE33: 01/08/2027 | AF33: =AD33+60 -> 2027 | AG33: 08056815710186 | AH33: 31/12/2008 | AI33: 84030059020 | AJ33: Islam | AK33: Perum Bumiasri Sengkaling FF-10 Mulyoagung Dau Malang | AL33: 4 | AM33: 5 | AN33: Sengkaling | AO33: Mulyoagung | AP33: Kec. Dau | AQ33: 65151 | AR33: 081217404962 | AS33: rinayuliawatisman1batu@gmail.com | AT33: 4602/104/C/89/SK | AU33: 13 Maret 1989 | AV33: 01/01/1989 | AW33: 10513/I04/C/90/SK | AX33: 31 Juli 1990 | AY33: 01/08/1990 | AZ33: Pemerintah Pusat | BA33: 823.3/63/SK/422.203/2011 | BB33: 20 Oktober 2011 | BC33: 01/10/2011 | BD33: Pemerintah Kota Batu | BE33: =K33 -> III/d | BF33: -- | BG33: -- | BH33: Harsusi | BI33: Kawin | BJ33: Nurkholis | BK33: 196607061991031001 | BL33: Tidak bekerja | BM33: Tidak | BN33: 570731992657000 | BO33: 0402141841 | BP33: 3507224807670002 | BQ33: 082139025141 | BV33: =R33+1 -> 27 | BX33: =T33+1 -> 35
A34: 27 | B34: Subari, S.Pd | C34: Malang, 12-03-1965 | D34: L | E34: 1 | G34: 196503121986031021 | H34: 19650312 198603 1 021 | I34: PNS | J34: Penata Tk. I, III/d | K34: III/d | L34: 01/04/2011 | O34: 01/03/1986 | P34: 3 | Q34: 0 | R34: 26 | S34: 4 | T34: 36 | U34: 4 | V34: S1 | X34: 1996 | AA34: Sosiologi | AB34: 4644743644200062 | AC34: =MID(G34,5,2) -> 03 | AD34: =MID(G34,1,4) -> 1965 | AE34: 01/04/2025 | AF34: =AD34+60 -> 2025 | AG34: 10056821410112 | AH34: 30/08/2010 | AI34: 101390892015 | AJ34: Islam | AK34: Ds. Tirtomoyo RT. 01 / RW. 01 Pakis Malang | AL34: 1 | AM34: 1 | AN34: Genitri | AO34: Tirtomoyo | AP34: Kec. Pakis | AQ34: 65154 | AR34: 082244174133 | AS34: subariirabus@gmail.com | AT34: 137.43/104/C/1986/SK | AU34: 30 Juli 1986 | AV34: 01/03/1986 | AW34: 11891/I04/C/87/SK | AX34: 5 Nopember 1987 | AY34: 01/12/1987 | AZ34: Pemerintah Pusat | BA34: 823.3/27/SK/422.203/2011 | BB34: 5 Mei 2011 | BC34: 01/04/2011 | BD34: Pemerintah Kota Batu | BE34: =K34 -> III/d | BF34: -- | BG34: -- | BH34: Kaseni | BI34: Kawin | BJ34: Siti Maslukah | BL34: Tidak bekerja | BM34: Tidak | BN34: 486370091657000 | BO34: 0402144645 | BP34: 35730212611570001 | BQ34: 082244174133 | BV34: =R34+1 -> 27 | BX34: =T34+1 -> 37
A35: 28 | B35: Sennawati, S.Pd | C35: Bone, 04-07-1968 | D35: P | F35: 1 | G35: 196807041998032006 | H35: 19680704 199803 2 006 | I35: PNS | J35: Penata Tk. I, III/d | K35: III/d | L35: 01/02/2011 | O35: 01/03/1998 | P35: 0 | Q35: 0 | R35: 22 | S35: 4 | T35: 22 | U35: 4 | V35: S1 | X35: 1990 | AA35: Bahasa Jerman | AB35: 4036746649300053 | AC35: =MID(G35,5,2) -> 07 | AD35: =MID(G35,1,4) -> 1968 | AE35: 01/08/2028 | AF35: =AD35+60 -> 2028 | AG35: 09056816010199 | AH35: 23/10/2009 | AI35: 091438407007 | AJ35: Islam | AK35: Jl. Bejo No. 10 D RT.02 / RW. 11 Sisir Batu | AL35: 2 | AM35: 11 | AN35: Sisir | AO35: Sisir | AP35: Kec. Batu | AQ35: 65314 | AR35: 081334190469 | AS35: senna.dayat@gmail.com | AT35: 2264/A2/KP/1998 | AU35: 11 Februari 1998 | AV35: 01/03/1998 | AW35: 821.12/138/429.207/2001 | AX35: 31 Oktober 2001 | AY35: 01/11/2001 | AZ35: Pemerintah Kab. Malang | BA35: 823.3/27/SK/422.203/2011 | BB35: 5 Mei 2011 | BC35: 01/02/2011 | BD35: Pemerintah Kota Batu | BE35: =K35 -> III/d | BF35: -- | BG35: -- | BH35: - | BI35: Kawin | BJ35: M. Hidayat | BK35: 196708301994031010 | BL35: PNS/TNI/Polri | BM35: Tidak | BN35: 474677374628000 | BO35: 0402142774 | BP35: 3579014407680002 | BQ35: 081334190469 | BV35: =R35+1 -> 23 | BX35: =T35+1 -> 23
A36: 29 | B36: Purwoto, S.Pd, M.Pd | C36: Malang, 25-07-1965 | D36: L | E36: 1 | G36: 196507252005011007 | H36: 19650725 200501 1 007 | I36: PNS | J36: Penata Tk. I, III/d | K36: III/d | L36: 01/04/2013 | O36: 01/01/2005 | P36: 4 | Q36: 7 | R36: 20 | S36: 1 | T36: 20 | U36: 1 | V36: S2 | X36: 2010 | Y36: SMAN 2 BATU | AA36: PKn | AB36: 1839743646200004 | AC36: =MID(G36,5,2) -> 07 | AD36: =MID(G36,1,4) -> 1965 | AE36: 01/08/2025 | AF36: =AD36+60 -> 2025 | AG36: 10056815410085 | AH36: 21/06/2010 | AI36: 102488392018 | AJ36: Islam | AK36: Jl. Raya Oro Oro Ombo RT. 02 / RW. 07 Oro Oro Ombo Batu | AL36: 2 | AM36: 7 | AN36: Oro oro Ombo | AO36: Oro Oro Ombo | AP36: Batu | AQ36: 65316 | AR36: 082244165163 | AS36: purwotobayu@gmail.com | AT36: 813.3/221/422.024/2005 | AU36: 1 April 2005 | AV36: 01/01/2005 | AW36: 821.13/219/SK/422.024/2006 | AX36: 1/9/2006 | AY36: 01/10/2006 | AZ36: Pemerintah Kota Batu | BA36: 823.3/16/SK/422.203/2013 | BB36: 8 April 2013 | BC36: 01/04/2013 | BD36: Pemerintah Kota Batu | BE36: =K36 -> III/d | BF36: -- | BG36: -- | BN36: 385719714628000 | BO36: 0402020466 | BP36: 3579012507650001 | BQ36: 082244165163 | BV36: =R36+1 -> 21 | BX36: =T36+1 -> 21
A37: 30 | B37: Anis Dyah Wahyuti, S.Pd | C37: Kediri,17-05-1975 | D37: P | F37: 1 | G37: 197505172000122001 | H37: 19750517 200012 2 001 | I37: PNS | J37: Penata Tk. I, III/d | K37: III/d | L37: 01/04/2011 | O37: 01/12/2000 | P37: 0 | Q37: 0 | R37: 19 | S37: 7 | T37: 19 | U37: 7 | V37: S1 | X37: 1999 | AA37: Fisika | AB37: 9849753655300032 | AC37: =MID(G37,5,2) -> 05 | AD37: =MID(G37,1,4) -> 1975 | AE37: 01/06/2035 | AF37: =AD37+60 -> 2035 | AG37: 09056818410200 | AH37: 27/07/2009 | AI37: 092087442002 | AJ37: Islam | AK37: Jl. Tenes No 30 RT. 01 / RW. 03 Sisir Batu | AL37: 1 | AM37: 3 | AN37: - | AO37: Sisir | AP37: Kec. Batu | AQ37: 65314 | AR37: 08123253881 | AS37: anissman1batu@gmail.com | AT37: 85552/A2/KP/2000 | AU37: 30 Desember 2000 | AV37: 01/12/2000 | AW37: 821.2/07/422.031/2002 | AX37: 28 Maret 2002 | AY37: 01/03/2002 | AZ37: Pemerintah Pusat | BA37: 823.3/27/SK/422.203/2011 | BB37: 5 Mei 2011 | BC37: 01/04/2011 | BD37: Pemerintah Kota Batu | BE37: =K37 -> III/d | BH37: Siti Maonah | BI37: Kawin | BJ37: Achmad Sudjoko | BK37: 31970560171275 | BL37: PNS/TNI/Polri | BM37: Tidak | BN37: 570732040628000 | BO37: 0402061626 | BP37: 3579015705760002 | BQ37: 08123253881 | BV37: =R37+1 -> 20 | BX37: =T37+1 -> 20
A38: 31 | B38: Deddy Iskandar, S.Sn | C38: Malang, 14-09-1969 | D38: L | E38: 1 | G38: 196909142005011013 | H38: 19690914 200501 1 013 | I38: PNS | J38: Penata Tk. I, III/d | K38: III/d | L38: 01/10/2016 | O38: 01/01/2005 | P38: 0 | Q38: 0 | R38: 15 | S38: 6 | T38: 15 | U38: 6 | V38: S1 | X38: 1994 | AA38: Seni Budaya | AB38: 6246747649200023 | AC38: =MID(G38,5,2) -> 09 | AD38: =MID(G38,1,4) -> 1969 | AE38: 01/10/2029 | AF38: =AD38+60 -> 2029 | AG38: 10056821710115 | AH38: 24/06/2010 | AI38: 101939412007 | AJ38: Islam | AK38: Jl. Cemara Kipas 05 RT. 01 / RW. 01 Sidomulyo Batu | AL38: 1 | AM38: 1 | AN38: Tinjumoyo | AO38: Sidomulyo | AP38: Kec. Batu | AQ38: 65317 | AR38: 081233344321 | AS38: deddy_kandar@yahoo.com | AT38: 813.3/147/422.024/2005 | AU38: 1 April 2005 | AV38: 01/01/2005 | AW38: 821.13/154/SK/422.024/2006 | AX38: 1 September 2006 | AY38: 01/10/2006 | AZ38: Pemerintah Pusat | BA38: 823.3/63/SK/422.203/2011 | BB38: 20 Oktober 2011 | BC38: 01/10/2016 | BD38: Pemerintah Kota Batu | BE38: =K38 -> III/d | BF38: -- | BG38: -- | BH38: Wahyuningsih | BI38: Kawin | BJ38: Erma Setyo Wahyuni | BL38: Wiraswasta | BM38: Tidak | BN38: 486370166628000 | BO38: 0402144581 | BP38: 3579011409690002 | BQ38: 081233344321 | BV38: =R38+1 -> 16 | BX38: =T38+1 -> 16
A39: 32 | B39: Iwan Yudi Hernawan, S.Pd, M.Pd. | C39: Blitar, 06-04-1975 | D39: L | E39: 1 | G39: 197504062005011016 | H39: 19750406 200501 1 016 | I39: PNS | J39: Penata Tk. I, III/d | K39: III/d | L39: 01/10/2017 | O39: 01/01/2005 | P39: 0 | Q39: 0 | R39: 15 | S39: 6 | T39: 15 | U39: 6 | V39: S2 | X39: 2009 | AA39: Bimbingan Konseling | AB39: 8738753654200002 | AC39: =MID(G39,5,2) -> 04 | AD39: =MID(G39,1,4) -> 1975 | AE39: 01/05/2035 | AF39: =AD39+60 -> 2035 | AG39: 11051581011850 | AH39: 01/10/2011 | AI39: 118101172002 | AJ39: Islam | AK39: Jl. Raya Giripurno 59/09 Bumiaji Batu | AL39: 59 | AM39: 9 | AN39: Kedung | AO39: Giripurno | AP39: Kec. Bumiaji | AQ39: 65333 | AR39: 08123399237 | AS39: iwansmangat@yahoo.co.id | AT39: 813.3/231/409.201/2005 | AU39: 12 April 2005 | AV39: 01/01/2005 | AW39: 813.3/239/409.201/2006 | AX39: 31 Juli 2006 | AY39: 01/08/2006 | AZ39: Pemerintah Kab/Kota | BA39: 823.3/1579/204/2017 | BB39: 4 September 2017 | BC39: 01/10/2017 | BD39: Pemerintah Provinsi | BE39: =K39 -> III/d | BF39: 821.2/1446/204/2017 | BG39: 14 Agustus 2017 | BH39: Sri Harmani | BI39: Kawin | BJ39: Wulandari | BL39: Tidak bekerja | BM39: Tidak | BN39: 485788897653000 | BO39: 0402181478 | BP39: 3579020604750003 | BQ39: 08123399237 | BV39: =R39+1 -> 16 | BX39: =T39+1 -> 16
A40: 33 | B40: Agustini Purwanti, M.Pd. | C40: Malang, 15 Agustus 1975 | D40: P | F40: 1 | G40: 197508152005012011 | H40: 19750815 200501 2 011 | I40: PNS | J40: Penata, III/c | K40: III/c | L40: 01/10/2019 | O40: 01/01/2005 | P40: 0 | Q40: 0 | R40: 15 | S40: 9 | T40: 15 | U40: 9 | V40: S2 | X40: 2017 | AA40: Fisika | AB40: 7147753654300033 | AC40: =MID(G40,5,2) -> 08 | AD40: =MID(G40,1,4) -> 1975 | AE40: 01/09/2035 | AF40: =AD40+60 -> 2035 | AG40: 10056818410120 | AH40: 30/08/2010 | AI40: 101988942006 | AJ40: Islam | AK40: Jl. Martorejo Gg. Melati No. 12 RT. 05 / RW. 02 Dadaprejo Junrejo Batu | AL40: 5 | AM40: 2 | AN40: Areng Areng | AO40: Dadap Rejo | AP40: Kec. Junrejo | AQ40: 65323 | AR40: 085334238817 | AS40: agustinipurwanti15@gmail.com | AT40: 8133/136/422.024/2005 | AU40: 1 April 2005 | AV40: 01/01/2005 | AW40: 813.13/143/SK/422.024/2006 | AX40: 1 September 2006 | AY40: 01/10/2006 | AZ40: Pemerintah Kab/Kota | BA40: 823.3/4016/204/2019 | BB40: 2 September 2019 | BC40: 01/10/2019 | BD40: Pemerintah Provinsi | BE40: =K40 -> III/c | BF40: 821.2/2420/204/2018 | BG40: 25 Oktober 2018 | BH40: Rupinah | BI40: Kawin | BJ40: Drs Sudaryanto | BL40: PNS/TNI/Polri | BM40: Tidak | BN40: 486360928628000 | BO40: 0402137355 | BP40: 3579035508750001 | BQ40: 085334238817 | BV40: =R40+1 -> 16 | BX40: =T40+1 -> 16
A41: 34 | B41: Drs. Pa'i | C41: Pasuruan, 23-01-1965 | D41: L | E41: 1 | G41: 196501232007011002 | H41: 19650123 200701 1 002 | I41: PNS | J41: Penata, III/c | K41: III/c | L41: 01/10/2016 | O41: 01/01/2007 | P41: 2 | Q41: 8 | R41: 16 | S41: 2 | T41: 16 | U41: 2 | V41: S1 | X41: 1991 | AA41: PKn | AB41: 2455743646200022 | AC41: =MID(G41,5,2) -> 01 | AD41: =MID(G41,1,4) -> 1965 | AE41: 01/02/2025 | AF41: =AD41+60 -> 2025 | AG41: 07056815490001 | AH41: 28/03/2008 | AI41: 072385392003 | AJ41: Islam | AK41: Jl. KH. Agus Salim II/09 RT. 02 / RW. 01 Sisir Batu | AL41: 2 | AM41: 2 | AO41: Sisir | AP41: Kec. Batu | AQ41: 65314 | AR41: 081803896255 | AS41: paibatu@gmail.com | AT41: 813.3/374/SK/422.024/2007 | AU41: 23 Desember 2007 | AV41: 01/01/2007 | AW41: 813.3/036.1/422.024/2009 | AX41: 16 April 2009 | AY41: 01/05/2009 | AZ41: Pemerintah Kab/Kota | BA41: 823.3/36/SK/422.203/2016 | BB41: 23 September 2016 | BC41: 01/10/2016 | BD41: Pemerintah Kota Batu | BE41: =K41 -> III/c | BF41: 821.2/030/SK/422.203/2010 | BG41: 30 April 2010 | BH41: Danah | BI41: Kawin | BJ41: Maslahah | BK41: 196511092007012016 | BL41: Tidak bekerja | BM41: Tidak | BN41: 871528501628000 | BO41: 0402037105 | BP41: 3579012301650001 | BQ41: 082232268907 | BV41: =R41+1 -> 17 | BX41: =T41+1 -> 17
...

Sheet DUK_GURU
A1: DAFTAR URUT KEPANGKATAN (DUK) TENAGA PENDIDIK SMAN 1 BATU
A2: PER OKTOBER 2026
A4: NO | B4: N A M A | C4: JENIS KEL. | D4: NIP | E4: MATPEL
E5: YANG DIAMPU
A6: 1 | B6: 2 | C6: 4 | D6: 5 | E6: 11
A7: 1 | B7: Anto Dwi Cahyono, S.Pd., M.M. | C7: L | D7: 19671023 199001 1 001 | E7: Kepala Sekolah
A8: =A7+1 -> 2 | B8: Drs. Hari Prasetyo | C8: L | D8: 19670523 199903 1 003 | E8: Penjaskes
A9: =A8+1 -> 3 | B9: Shinta Amalia, S.Pd. M. Pd. | C9: P | D9: 19681220 199412 2 002 | E9: Kimia
A10: =A9+1 -> 4 | B10: Abdul Khamid, S.Pd | C10: L | D10: 19690821 199403 1 005 | E10: PKn
A11: =A10+1 -> 5 | B11: Iwan Yudi Hernawan, S.Pd, M.Pd. | C11: L | D11: 19750406 200501 1 016 | E11: BK
A12: =A11+1 -> 6 | B12: Sennawati, S.Pd | C12: P | D12: 19680704 199803 2 006 | E12: B.Jerman
A13: =A12+1 -> 7 | B13: Anis Dyah Wahyuti, S.Pd | C13: P | D13: 19750517 200012 2 001 | E13: Fisika
A14: =A13+1 -> 8 | B14: Reny Widayanti, S.E. | C14: P | D14: 19721203 200604 2 005 | E14: Ekonomi
A15: =A14+1 -> 9 | B15: Umi Solikah, S.Pd. | C15: P | D15: 19710413 200604 2 023 | E15: Biologi
A16: =A15+1 -> 10 | B16: Hermawanto, S.Pd, M.Pd. | C16: L | D16: 19830219 200604 1 011 | E16: Fisika
A17: =A16+1 -> 11 | B17: Agustini Purwanti, S. Pd., M. Pd. | C17: P | D17: 19750815 200501 2 011 | E17: Fisika
A18: =A17+1 -> 12 | B18: Nita Rimayanti, S.Pd. | C18: P | D18: 19860728 200903 2 005 | E18: Ekonomi
A19: =A18+1 -> 13 | B19: Dewi Insyasiska, S. Pd., M. Pd. | C19: P | D19: 19780823 200604 2 029 | E19: Biologi
... A35: =A34+1 -> 29 | B35: Anas Bachtiar, S.Pd. | C35: L | D35: 19840716 200903 1 005 | E35: Penjaskes
A37: PPPK
A38: 1 | B38: Juhadi Ishak, S.Pd | C38: L | D38: 19790709 202221 1 012 | E38: PJOK
A39: 2 | B39: Ahmad Muhajir RH, S.Pd | C39: L | D39: 19820826 202221 1 011 | E39: PJOK
A40: 3 | B40: Suwil Roidah, S.Pd | C40: P | D40: 19840712 202221 2 044 | E40: Ekonomi
A41: 4 | B41: Mardiyah Putri Astuti, M.Pd. | C41: P | D41: 19900321 202221 2 012 | E41: B.Indonesia
A42: 5 | B42: Lailaus Naeni, S.S., S.Pd | C42: P | D42: 19900507 202221 2 016 | E42: B.Indonesia
A43: 6 | B43: Didik Eko Susanto, S. Psi. | C43: L | D43: 19760326 202221 1 003 | E43: BK
A44: 7 | B44: Moh. Irham Rozaki S. Kom. Gr. | C44: L | D44: 19891021 202221 1 017 | E44: Informatika
A45: 8 | B45: Widya Ningsih, S. Kom. | C45: P | D45: 19830912 202221 2 036 | E45: Informatika
A46: 9 | B46: Abdul Aziz S.Kom | C46: L | D46: 19940623 202221 1 006 | E46: Informatika
A47: 10 | B47: Aviv Ardhillah Risqa, S.Pd | C47: L | D47: 198912042023211016 | E47: Matematika
A48: 11 | B48: Amitha Mustika Dhamayanti, S .Pd. | C48: P | D48: 199202192023212039 | E48: Sejarah
A49: 12 | B49: Sri Nurhayani, S.Pd | C49: P | D49: 199208142023212042 | E49: B.Indonesia
... A57: 20 | B57: Ratih Sukmawati,S.Pd | C57: P | D57: 198008022024212014 | E57: Matematika
A58: PPKW
A59: 1 | B59: Ribkha Ayu Adiningtyas, M.Pd. | C59: P | D59: 199203222025212115 | E59: Sejarah
A60: 2 | B60: Panji Penatas, S.Pd. | C60: L | D60: 199006082025211127 | E60: Sejarah
A61: GTT
A62: 1 | B62: Restu Lenny Medikawati, S.Pd. | C62: P | D62: 20536817170896012005592 | E62: Bahasa Jawa
A63: 2 | B63: Elsa Firda Yustika, S. Pd. | C63: P | D63: 20536817251098012205590 | E63: Sosiologi
A64: 3 | B64: Damaola Via M, S. Pd. | C64: P | D64: 20536817140795012205587 | E64: Geografi
...

Sheet LABEL NAMA URUT 
A1: 1 | B1: Ritul Idha Djarwati,S.Pd., M.Pd.
A2: 2 | B2: Dra Nurhayati,S.H
A3: 3 | B3: Drs. Sugiardi, M.M.
A4: 4 | B4: Ririn Andriana, M.Pd.
A5: 5 | B5: Tri Sakti Andayani. M.Pd
A6: 6 | B6: Sri Wati, S.Pd, M.M.
A7: 7 | B7: Drs Awwaludin,M.Pd
A8: 8 | B8: Yudiono, S.Pd
A9: 9 | B9: Shinta Amalia, M.Pd
A10: 10 | B10: Dra. Mustaghfiroh
A11: 11 | B11: Abdul Khamid, S.Pd
A12: 12 | B12: Tatang Yuli Ahmadi, M.Pd
... A95: 95 | B95: Mochammad Efendi

Sheet data absen
A1: NO | B1: NAMA | C1: JABATAN | D1: STATUS KEPEGAWAIAN
A2: 1 | B2: Anto Dwi Cahyono, S.Pd., M.M. | C2: Guru | D2: ASN
A3: =A2+1 -> 2 | B3: Drs. Hari Prasetyo | C3: Guru | D3: ASN
A4: =A3+1 -> 3 | B4: Shinta Amalia, S.Pd. M. Pd. | C4: Guru | D4: ASN
A5: =A4+1 -> 4 | B5: Abdul Khamid, S.Pd | C5: Guru | D5: ASN
A6: =A5+1 -> 5 | B6: Iwan Yudi Hernawan, S.Pd, M.Pd. | C6: Guru | D6: ASN
A7: =A6+1 -> 6 | B7: Sennawati, S.Pd | C7: Guru | D7: ASN
A8: =A7+1 -> 7 | B8: Anis Dyah Wahyuti, S.Pd | C8: Guru | D8: ASN
A9: =A8+1 -> 8 | B9: Reny Widayanti, S.E. | C9: Guru | D9: ASN
A10: =A9+1 -> 9 | B10: Umi Solikah, S.Pd. | C10: Guru | D10: ASN
A11: =A10+1 -> 10 | B11: Hermawanto, S.Pd, M.Pd. | C11: Guru | D11: ASN
A12: =A11+1 -> 11 | B12: Agustini Purwanti, S. Pd., M. Pd. | C12: Guru | D12: ASN
A13: =A12+1 -> 12 | B13: Nita Rimayanti, S.Pd. | C13: Guru | D13: ASN
A14: =A13+1 -> 13 | B14: Dewi Insyasiska, S. Pd., M. Pd. | C14: Guru | D14: ASN
... A57: =A56+1 -> 56 | B57: Tias Maulidina W, S. Psi. | C57: Guru | D57: GTT
A58: =A90+1 -> 88 | B58: Devi Astri Wardiningtyas, S.Pd. | C58: Guru | D58: GTT
A59: =A58+1 -> 89 | B59: Ririn Budi Hartini, S. Ag | C59: Guru | D59: Guru DPK
A60: =A57+1 -> 57 | B60: Sisca Tri Hersa, S. Pd. | C60: Guru | D60: Guru DPK
A61: =A60+1 -> 58 | B61: Fera Irawati, S.Pd. | C61: Tenaga Kependidikan | D61: ASN
A62: =A61+1 -> 59 | B62: Hasdian Lestyarini, A.Md | C62: Tenaga Kependidikan | D62: ASN
A63: =A62+1 -> 60 | B63: Yanto, S.Mat. | C63: Tenaga Kependidikan | D63: ASN
A64: =A63+1 -> 61 | B64: Muhaimin, S.E. | C64: Tenaga Kependidikan | D64: ASN
A65: =A64+1 -> 62 | B65: Rositha Chaironi | C65: Tenaga Kependidikan | D65: ASN
A66: =A65+1 -> 63 | B66: Sulisno, A.Md | C66: Tenaga Kependidikan | D66: ASN
A67: =A66+1 -> 64 | B67: Andrias Budi Widodo | C67: Tenaga Kependidikan | D67: ASN
A68: =A67+1 -> 65 | B68: Aida Purwanti Cholifah, A.Md | C68: Laboran | D68: ASN
A69: =A68+1 -> 66 | B69: Mochammad Hadi Muslimin | C69: Tenaga Kependidikan | D69: ASN
A70: =A69+1 -> 67 | B70: Rindy Antika Sari | C70: Tenaga Kependidikan | D70: ASN
A71: =A70+1 -> 68 | B71: Soleh | C71: Tenaga Kependidikan | D71: ASN
A72: =A71+1 -> 69 | B72: Dedik Rubianto | C72: Tenaga Kependidikan | D72: ASN
... A90: =A89+1 -> 87 | B90: Tony Fitriyanto | C90: Outsourcing | D90: Satpam
A91: =A59+1 -> 90 | B91: Samsul Arifin | C91: Outsourcing | D91: Cleaning Service

Sheet REKAP TENDIK SMAN 1 BATU
A1: DAFTAR URUT KEPANGKATAN (DUK) TENAGA KEPENDIDIKAN SMAN 1 BATU
A2: PER 1 JULI 2024
A3: TENAGA PENDIDIK | B3: Jumlah | E3: KUALIFIKASI PENDIDIKAN
B4: Jenis Kelamin | D4: Jumlah
B5: Lk | C5: Pr | E5: S2 | F5: S1 | G5: D3 | H5: SMA | I5: SMK
A6: PNS | B6: 18 | C6: 24 | D6: 42 | E6: 16 | F6: 27 | H6: - | I6: -
A7: PPPK | B7: 9 | C7: 14 | D7: 23 | E7: 2 | F7: 21 | H7: - | I7: -
A8: GTT | B8: 1 | C8: 7 | D8: =SUM(B8:C8) -> 8 | E8: - | F8: 8 | H8: - | I8: -
A9: TENAGA KEPENDIDIKAN | B9: JUMLAH | D9: =SUM(D6:D8) -> 73
A10: PNS | B10: 6 | C10: 3 | D10: 9 | E10: - | F10: 4 | G10: 1 | H10: - | I10: -
A11: PTT | B11: 13 | C11: 4 | D11: 17 | E11: - | F11: - | H11: 11 | I11: 4
A12: OUSORSING | B12: 2 | C12: - | D12: 2 | E12: - | F12: - | H12: - | I12: -
B13: JUMLAH | D13: =SUM(D10:D12) -> 28
D14: =SUM(D9,D13) -> 101
E16: Batu 1 Juli 2024
E17: Kepala Sekolah,
E21: Ritul Idha Djarwati,S.Pd., M.Pd.
E22: NIP. 19650110 198803 2 011

Sheet Sheet3
A1: GTT | B1: NUPTK
A2: Diana Irawati,S.Pd | B2: 1242759663300000
A3: Defri Mustika Rani, M.Pd. | B3: 9760767668130182
A4: Ribkha Ayu Adiningtyas, M.Pd. | B4: 4654770671130102
A5: Amitha Mustika Damayanti, M .Pd. | B5: 0551770671130132
A6: Aviv Ardhillah Risqa, S.Pd | B6: 8536767668130183
A7: Yeni Tri Wulandari, S.Pd | B7: 4437761662230192
A8: Panji Penatas, S.Pd.
A9: GTT | B9: NO NUPTK
A10: Restu Lenny Medikawati, S.Pd.
A11: Latih Yusdiansah, S.Pd.
A12: Elsa Firda Yustika, S. Pd.
A13: Yolanda Via Susanti, S. Pd.
A14: Eka Hidayatul M, S. Pd. I
A15: M. Syamsu Hidayat, S. Pd.
A16: Damaola Via M, S. Pd.
A17: Sivira Anggriani, S. Pd.
A18: Tias Maulidina W, S. Psi.
A20: PTT | B20: NUPTK
A21: Rindy Antika Sari | B21: 1834766661300002
A22: Soleh | B22: 5536757660200013
A23: Hari Purnomo | B23: 3544743645200023
A24: Dedik Rubianto | B24: 1541756668200003
A25: Sulis Setiasih | B25: 5439768669300002
A26: Ngari | B26: 7748751653200042
A27: Siti Nurlatifah | B27: 4835768669300002
A28: Timbul Hariwibadi | B28: 3752754657110022
A29: Santo | B29: 3050751652130093
A30: Untung Supriono Basuki | B30: 3035758659130133
A31: Arif Afandi | B31: 3240754656200043
... A39: Mochammad Efendi | B39: 0833764665130242

Sheet Data_BUP
A1: DATA BATAS USIA PENSIUN (BUP)
A2: SMA NEGERI I BATU
A3: TAHUN 2019
A5: FUNGSIONAL
A6: NO | B6: N A M A | C6: JENIS KEL. | D6: NIP | E6: PANGKAT | G6: TEMPAT & TGL.LAHIR | H6: BUP | I6: USUL PENSIUN
E7: GOL | F7: TMT
A8: 1 | B8: =DATA!B8 -> Edy Parlindungan.S.Pd,M.M | C8: L | D8: =DATA!G8 -> 19630326 1989031007 | E8: =DATA!K8 -> IV/b | F8: =DATA!L8 -> 41365 | G8: =DATA!C8 -> Maga, 26 Maret 1963 | H8: =DATA!AE8 -> 45017
A9: 2 | B9: =DATA!B9 -> Ismi Yunaeni, S.Pd, M.Pd | C9: =DATA!D9 -> P | D9: =DATA!G9 -> 196106021985122002 | E9: =DATA!K9 -> IV/b | F9: =DATA!L9 -> 01/04/2011 | G9: =DATA!C9 -> Jember,02-06-1961 | H9: =DATA!AE9 -> 01/07/2021
A10: 3 | B10: =DATA!B10 -> Lilik Ismiati, M.Pd | C10: =DATA!D10 -> P | D10: =DATA!G10 -> 196307261987032007 | E10: =DATA!K10 -> IV/b | F10: =DATA!L10 -> 01/04/2014 | G10: =DATA!C10 -> Malang, 26-07-1963 | H10: =DATA!AE10 -> 01/08/2023
A11: 4 | B11: =DATA!B11 -> Dra. Nurhidayati, Sh, M.Pd. | C11: =DATA!D11 -> P | D11: =DATA!G11 -> 196509181988032007 | E11: =DATA!K11 -> IV/b | F11: =DATA!L11 -> 01/10/2013 | G11: =DATA!C11 -> Tulung Agung,18-9-1965 | H11: =DATA!AE11 -> 01/10/2025
A12: 5 | B12: =DATA!B12 -> Drs. Sugiardi, M.M. | C12: =DATA!D12 -> L | D12: =DATA!G12 -> 196406241995121002 | E12: =DATA!K12 -> IV/b | F12: =DATA!L12 -> 01/04/2019 | G12: =DATA!C12 -> Malang,24-06-1964 | H12: =DATA!AE12 -> 01/07/2024
A13: 6 | B13: =DATA!B13 -> Sri Wati, S.Pd, M.M. | C13: =DATA!D13 -> P | D13: =DATA!G13 -> 196404191984122005 | E13: =DATA!K13 -> IV/a | F13: =DATA!L13 -> 01/10/2005 | G13: =DATA!C13 -> Malang,19-04-1964 | H13: =DATA!AE13 -> 01/05/2024
A14: 7 | B14: =DATA!B14 -> Amantho, S.Pd | C14: =DATA!D14 -> L | D14: =DATA!G14 -> 196203151985111002 | E14: =DATA!K14 -> IV/a | F14: =DATA!L14 -> 01/04/2005 | G14: =DATA!C14 -> Banyuwangi, 15-03-1962 | H14: =DATA!AE14 -> 01/04/2022
A15: 8 | B15: =DATA!B15 -> Yayuk Harumiwati, S.Pd | C15: =DATA!D15 -> P | D15: =DATA!G15 -> 196111071985122002 | E15: =DATA!K15 -> IV/a | F15: =DATA!L15 -> 01/04/2006 | G15: =DATA!C15 -> Malang,07-11-1961 | H15: =DATA!AE15 -> 01/12/2021
A16: 9 | B16: =DATA!B16 -> Ninil Agus Triastuti, S.Pd | C16: =DATA!D16 -> P | D16: =DATA!G16 -> 196308111985122002 | E16: =DATA!K16 -> IV/a | F16: =DATA!L16 -> 01/04/2006 | G16: =DATA!C16 -> Malang,11-08-1963 | H16: =DATA!AE16 -> 01/09/2023
A17: 10 | B17: =DATA!B17 -> Dra. Amalia Ujinastiti | C17: =DATA!D17 -> P | D17: =DATA!G17 -> 196205291989032004 | E17: =DATA!K17 -> IV/a | F17: =DATA!L17 -> 01/04/2002 | G17: =DATA!C17 -> Yogyakarta, 29-5-1962 | H17: =DATA!AE17 -> 01/06/2022
A18: 11 | B18: =DATA!B18 -> Dra. Shofiyatuz Zahra | C18: =DATA!D18 -> P | D18: =DATA!G18 -> 196112121989022003 | E18: =DATA!K18 -> IV/a | F18: =DATA!L18 -> 01/04/2005 | G18: =DATA!C18 -> Nganjuk,12-12-1961 | H18: =DATA!AE18 -> 01/01/2022
A19: 12 | B19: =DATA!B19 -> Mudrikah Hayati, S.Pd | C19: =DATA!D19 -> P | D19: =DATA!G19 -> 196306221987032006 | E19: =DATA!K19 -> IV/a | F19: =DATA!L19 -> 01/04/2006 | G19: =DATA!C19 -> Blitar,22-06-1963 | H19: =DATA!AE19 -> 01/07/2023
A20: 13 | B20: =DATA!B20 -> Tri Sakti Andayani. M.Pd | C20: =DATA!D20 -> P | D20: =DATA!G20 -> 196508261988032015 | E20: =DATA!K20 -> IV/a | F20: =DATA!L20 -> 01/04/2005 | G20: =DATA!C20 -> Trenggalek,26-8-1965 | H20: =DATA!AE20 -> 01/09/2025
... A65: 59 | B65: =DATA!B65 -> Eko Prayudi, Lc | C65: =DATA!D65 -> L | D65: =DATA!G65 -> 197812092011011007 | E65: =DATA!K65 -> III/a | F65: =DATA!L65 -> 01/01/2013 | G65: =DATA!C65 -> Ponorogo, 09-12-1978 | H65: =DATA!AE65 -> 01/01/2039
A73: STRUKTURAL
A74: NO | B74: N A M A | C74: JENIS KEL. | D74: NIP | E74: PANGKAT | G74: TEMPAT & TGL.LAHIR | H74: BUP | I74: USUL PENSIUN
E75: GOL | F75: TMT
A76: 1 | B76: =DATA!B85 -> Fera Irawati, S.Pd. | C76: =DATA!D85 -> P | D76: =DATA!G85 -> 198102232005012006 | E76: =DATA!K85 -> III/d | F76: =DATA!L85 -> 01/10/2017 | G76: =DATA!C85 -> Malang, 23-02-1981 | H76: =DATA!AE85 -> 01/03/2039
A77: 2 | B77: =DATA!B86 -> Sri Mulyati, A.Md.Pd | C77: =DATA!D86 -> P | D77: =DATA!G86 -> 196409142008012004 | E77: =DATA!K86 -> III/a | F77: =DATA!L86 -> 01/10/2016 | G77: =DATA!C86 -> Malang, 14-09-1964 | H77: =DATA!AE86 -> 01/10/2022
A78: 3 | B78: =DATA!B87 -> Hasdian Lestyarini, A.Md | C78: =DATA!D87 -> P | D78: =DATA!G87 -> 196809142010012001 | E78: =DATA!K87 -> III/a | F78: =DATA!L87 -> 01/04/2018 | G78: =DATA!C87 -> Banyuwangi, 14-09-1968 | H78: =DATA!AE87 -> 01/10/2026
A79: 4 | B79: =DATA!B88 -> Yanto, S.Mat. | C79: =DATA!D88 -> L | D79: =DATA!G88 -> 198510302006041010 | E79: =DATA!K88 -> II/d | F79: =DATA!L88 -> 01/04/2018 | G79: =DATA!C88 -> Malang, 30-10-1985 | H79: =DATA!AE88 -> 01/11/2043
A80: 5 | B80: =DATA!B89 -> Mohamad Tamtowi, S.E. | C80: =DATA!D89 -> L | D80: =DATA!G89 -> 196609222010011001 | E80: =DATA!K89 -> II/c | F80: =DATA!L89 -> 01/04/2018 | G80: =DATA!C89 -> Malang, 22-09-1966 | H80: =DATA!AE89 -> 01/10/2024
A81: 6 | B81: =DATA!B90 -> Muhaimin, S.E. | C81: =DATA!D90 -> L | D81: =DATA!G90 -> 197810102009031002 | E81: =DATA!K90 -> II/c | F81: =DATA!L90 -> 01/04/2018 | G81: =DATA!C90 -> Malang, 10-10-1978 | H81: =DATA!AE90 -> 01/11/2036
A82: 7 | B82: =DATA!B91 -> Sholikhin | C82: =DATA!D91 -> L | D82: =DATA!G91 -> 196605242010011002 | E82: =DATA!K91 -> II/c | F82: =DATA!L91 -> 01/04/2018 | G82: =DATA!C91 -> Malang, 24-05-1966 | H82: =DATA!AE91 -> 01/06/2024
A83: 8 | B83: =DATA!B92 -> Rositha Chaironi | C83: =DATA!D92 -> P | D83: =DATA!G92 -> 197107212010012001 | E83: =DATA!K92 -> II/c | F83: =DATA!L92 -> 01/04/2018 | G83: =DATA!C92 -> Batu, 21-07-1971 | H83: =DATA!AE92 -> 01/08/2029
A84: 9 | B84: =DATA!B93 -> Sulisno, A.Md | C84: =DATA!D93 -> L | D84: =DATA!G93 -> 197901102014121001 | E84: =DATA!K93 -> II/b | F84: =DATA!L93 -> 01/03/2019 | G84: =DATA!C93 -> Malang, 01-10-1979 | H84: =DATA!AE93 -> 01/11/2037
A85: 10 | B85: =DATA!B94 -> Andrias Budi Widodo | C85: =DATA!D94 -> L | D85: =DATA!G94 -> 198109162014121001 | E85: =DATA!K94 -> II/b | F85: =DATA!L94 -> 01/03/2019 | G85: =DATA!C94 -> Malang, 16-09-1981 | H85: =DATA!AE94 -> 01/10/2039
A86: 11 | B86: =DATA!B95 -> Heri Kristiawan | C86: =DATA!D95 -> L | D86: =DATA!G95 -> 196711102008011020 | E86: =DATA!K95 -> II/b | F86: =DATA!L95 -> 01/04/2020 | G86: =DATA!C95 -> Malang, 10-11-1967 | H86: =DATA!AE95 -> 01/12/2025
G88: Batu, 1 Juli 2019
G89: Kasubag. Tata Usaha
G93: Edy Purwanto
G94: NIP. 19630413 108602 1 006
A95: DATA BATAS USIA PENSIUN (BUP)
A96: SMA NEGERI I BATU
...
